Workbook

Sheet 펌프리스트
A1: 대체모델명 | B1: NO | C1: 모델명 | D1: 물품대 | E1: 인터넷 권장가 | F1: 필터 최저가 | G1: 필터 최고가 | H1: DC | I1: 윌로펌프백화점 | J1: LG윌로펌프 | K1: WILO 대리점
A2: PW-952LMA/h | B2: 1 | C2: PW-952LMA | D2: =_xlfn.XLOOKUP(A2,[1]생활용펌프가격표!$A:$A,[1]생활용펌프가격표!$B:$B,0) -> 663000 | E2: =_xlfn.XLOOKUP(A2,[1]생활용펌프가격표!$A:$A,[1]생활용펌프가격표!$C:$C,0) -> 584000 | H2: =1-E2/1.1/D2 -> 0.19923214 | I2: 오아시스 펌프 | J2: 경동기전 | K2: WILO 대리점
B3: 2 | C3: PW-601LMA | D3: =_xlfn.XLOOKUP(C3,[1]생활용펌프가격표!$A:$A,[1]생활용펌프가격표!$B:$B,0) -> 513000 | E3: =_xlfn.XLOOKUP(C3,[1]생활용펌프가격표!$A:$A,[1]생활용펌프가격표!$C:$C,0) -> 452000 | H3: =1-E3/1.1/D3 -> 0.19900762 | I3: 서울피엠 | J3: 경동기전 | K3: WILO 대리점
B4: 3 | C4: PW-600SMA | D4: =_xlfn.XLOOKUP(C4,[1]생활용펌프가격표!$A:$A,[1]생활용펌프가격표!$B:$B,0) -> 336000 | E4: =_xlfn.XLOOKUP(C4,[1]생활용펌프가격표!$A:$A,[1]생활용펌프가격표!$C:$C,0) -> 296000 | H4: =1-E4/1.1/D4 -> 0.1991342 | I4: 펌프365 | J4: 고강C&P | K4: WILO 대리점
B5: 4 | C5: PW-600M | D5: =_xlfn.XLOOKUP(C5,[1]생활용펌프가격표!$A:$A,[1]생활용펌프가격표!$B:$B,0) -> 312000 | E5: =_xlfn.XLOOKUP(C5,[1]생활용펌프가격표!$A:$A,[1]생활용펌프가격표!$C:$C,0) -> 275000 | H5: =1-E5/1.1/D5 -> 0.19871795 | I5: 윌로펌프총판 | J5: 광진종합상사 | K5: WILO 대리점
B6: 5 | C6: PW-350SMA | D6: =_xlfn.XLOOKUP(C6,[1]생활용펌프가격표!$A:$A,[1]생활용펌프가격표!$B:$B,0) -> 249000 | E6: =_xlfn.XLOOKUP(C6,[1]생활용펌프가격표!$A:$A,[1]생활용펌프가격표!$C:$C,0) -> 220000 | H6: =1-E6/1.1/D6 -> 0.19678715 | I6: 펌프굿 | J6: 굿펌프 | K6: WILO 대리점
B7: 6 | C7: PW-350M | D7: =_xlfn.XLOOKUP(C7,[1]생활용펌프가격표!$A:$A,[1]생활용펌프가격표!$B:$B,0) -> 253000 | E7: =_xlfn.XLOOKUP(C7,[1]생활용펌프가격표!$A:$A,[1]생활용펌프가격표!$C:$C,0) -> 223000 | H7: =1-E7/1.1/D7 -> 0.19870643 | I7: 나인티에스 | J7: 나인티에스 | K7: WILO 대리점
B8: 7 | C8: PW-200SMA | D8: =_xlfn.XLOOKUP(C8,[1]생활용펌프가격표!$A:$A,[1]생활용펌프가격표!$B:$B,0) -> 209000 | E8: =_xlfn.XLOOKUP(C8,[1]생활용펌프가격표!$A:$A,[1]생활용펌프가격표!$C:$C,0) -> 184000 | H8: =1-E8/1.1/D8 -> 0.19965202 | I8: 펌프파트너 | J8: 나인티에스 | K8: WILO 대리점
B9: 8 | C9: PW-200M | D9: =_xlfn.XLOOKUP(C9,[1]생활용펌프가격표!$A:$A,[1]생활용펌프가격표!$B:$B,0) -> 209000 | E9: =_xlfn.XLOOKUP(C9,[1]생활용펌프가격표!$A:$A,[1]생활용펌프가격표!$C:$C,0) -> 184000 | H9: =1-E9/1.1/D9 -> 0.19965202 | I9: 이엔지마켓 | J9: 대림상사 | K9: WILO 대리점
B10: 9 | C10: PU-S604M | D10: =_xlfn.XLOOKUP(C10,[1]생활용펌프가격표!$A:$A,[1]생활용펌프가격표!$B:$B,0) -> 292000 | E10: =_xlfn.XLOOKUP(C10,[1]생활용펌프가격표!$A:$A,[1]생활용펌프가격표!$C:$C,0) -> 257000 | H10: =1-E10/1.1/D10 -> 0.19987547 | I10: 따뜻함 | J10: 대영상사 | K10: WILO 대리점
B11: 10 | C11: PU-S600M | D11: =_xlfn.XLOOKUP(C11,[1]생활용펌프가격표!$A:$A,[1]생활용펌프가격표!$B:$B,0) -> 281000 | E11: =_xlfn.XLOOKUP(C11,[1]생활용펌프가격표!$A:$A,[1]생활용펌프가격표!$C:$C,0) -> 248000 | H11: =1-E11/1.1/D11 -> 0.19767066 | I11: 펌프산업 | J11: 대풍상사 | K11: WILO 대리점
A12: PU-951M/h | B12: 11 | C12: PU-951M | D12: =_xlfn.XLOOKUP(A12,[1]생활용펌프가격표!$A:$A,[1]생활용펌프가격표!$B:$B,0) -> 432000 | E12: =_xlfn.XLOOKUP(A12,[1]생활용펌프가격표!$A:$A,[1]생활용펌프가격표!$C:$C,0) -> 381000 | H12: =1-E12/1.1/D12 -> 0.19823232 | I12: 워터테크 | J12: 대풍상사 | K12: WILO 대리점
A13: PU-950M/h | B13: 12 | C13: PU-950M | D13: =_xlfn.XLOOKUP(A13,[1]생활용펌프가격표!$A:$A,[1]생활용펌프가격표!$B:$B,0) -> 432000 | E13: =_xlfn.XLOOKUP(A13,[1]생활용펌프가격표!$A:$A,[1]생활용펌프가격표!$C:$C,0) -> 381000 | H13: =1-E13/1.1/D13 -> 0.19823232 | I13: 펌프닷컴 | J13: 대풍상사 | K13: WILO 대리점
B14: 13 | C14: PU-651M | D14: =_xlfn.XLOOKUP(C14,[1]생활용펌프가격표!$A:$A,[1]생활용펌프가격표!$B:$B,0) -> 240000 | E14: =_xlfn.XLOOKUP(C14,[1]생활용펌프가격표!$A:$A,[1]생활용펌프가격표!$C:$C,0) -> 212000 | H14: =1-E14/1.1/D14 -> 0.1969697 | I14: 윌로프로 | J14: 미라클YT펌프 | K14: WILO 대리점
B15: 14 | C15: PU-602M | D15: =_xlfn.XLOOKUP(C15,[1]생활용펌프가격표!$A:$A,[1]생활용펌프가격표!$B:$B,0) -> 239000 | E15: =_xlfn.XLOOKUP(C15,[1]생활용펌프가격표!$A:$A,[1]생활용펌프가격표!$C:$C,0) -> 211000 | H15: =1-E15/1.1/D15 -> 0.19741347 | I15: 샌프란시스코2 | J15: 삼흥E&P | K15: WILO 대리점
B16: 15 | C16: PU-350M | D16: =_xlfn.XLOOKUP(C16,[1]생활용펌프가격표!$A:$A,[1]생활용펌프가격표!$B:$B,0) -> 228000 | E16: =_xlfn.XLOOKUP(C16,[1]생활용펌프가격표!$A:$A,[1]생활용펌프가격표!$C:$C,0) -> 201000 | H16: =1-E16/1.1/D16 -> 0.19856459 | I16: pump-damoa | J16: 서울종합펌프 | K16: WILO 대리점
B17: 16 | C17: PH-K043M | D17: =_xlfn.XLOOKUP(C17,[1]생활용펌프가격표!$A:$A,[1]생활용펌프가격표!$B:$B,0) -> 64700 | E17: =_xlfn.XLOOKUP(C17,[1]생활용펌프가격표!$A:$A,[1]생활용펌프가격표!$C:$C,0) -> 57000 | H17: =1-E17/1.1/D17 -> 0.19910074 | I17: 서울펌프몰 | J17: 서울펌프랜드 | K17: WILO 대리점
B18: 17 | C18: PH-080M | D18: =_xlfn.XLOOKUP(C18,[1]생활용펌프가격표!$A:$A,[1]생활용펌프가격표!$B:$B,0) -> 118000 | E18: =_xlfn.XLOOKUP(C18,[1]생활용펌프가격표!$A:$A,[1]생활용펌프가격표!$C:$C,0) -> 104000 | H18: =1-E18/1.1/D18 -> 0.19876733 | I18: 윌로공식 SKS윌로펌프 | J18: 세광사 | K18: WILO 대리점
B19: 18 | C19: PH-046M | D19: =_xlfn.XLOOKUP(C19,[1]생활용펌프가격표!$A:$A,[1]생활용펌프가격표!$B:$B,0) -> 46100 | E19: =_xlfn.XLOOKUP(C19,[1]생활용펌프가격표!$A:$A,[1]생활용펌프가격표!$C:$C,0) -> 41000 | H19: =1-E19/1.1/D19 -> 0.19148097 | I19: 수중모터주식회사 | J19: 수중모터주식회사 | K19: WILO 대리점
B20: 19 | C20: PH-045M | D20: =_xlfn.XLOOKUP(C20,[1]생활용펌프가격표!$A:$A,[1]생활용펌프가격표!$B:$B,0) -> 46100 | E20: =_xlfn.XLOOKUP(C20,[1]생활용펌프가격표!$A:$A,[1]생활용펌프가격표!$C:$C,0) -> 41000 | H20: =1-E20/1.1/D20 -> 0.19148097 | I20: 시대몰 | J20: 시대상사 | K20: WILO 대리점
B21: 20 | C21: PDV-A950MA | D21: =_xlfn.XLOOKUP(C21,[1]생활용펌프가격표!$A:$A,[1]생활용펌프가격표!$B:$B,0) -> 416000 | E21: =_xlfn.XLOOKUP(C21,[1]생활용펌프가격표!$A:$A,[1]생활용펌프가격표!$C:$C,0) -> 367000 | H21: =1-E21/1.1/D21 -> 0.19798951 | I21: 펌프프렌드 | J21: 에스에이치테크 | K21: WILO 대리점
B22: 21 | C22: PDV-A950M | D22: =_xlfn.XLOOKUP(C22,[1]생활용펌프가격표!$A:$A,[1]생활용펌프가격표!$B:$B,0) -> 392000 | E22: =_xlfn.XLOOKUP(C22,[1]생활용펌프가격표!$A:$A,[1]생활용펌프가격표!$C:$C,0) -> 345000 | H22: =1-E22/1.1/D22 -> 0.19990724 | I22: 윌로펌프마켓 | J22: 엘지산업 | K22: WILO 대리점
B23: 22 | C23: PDV-A600M | D23: =_xlfn.XLOOKUP(C23,[1]생활용펌프가격표!$A:$A,[1]생활용펌프가격표!$B:$B,0) -> 311000 | E23: =_xlfn.XLOOKUP(C23,[1]생활용펌프가격표!$A:$A,[1]생활용펌프가격표!$C:$C,0) -> 274000 | H23: =1-E23/1.1/D23 -> 0.1990646 | I23: 윌로종합 | J23: 윌로종합상사 영천 | K23: WILO 대리점
B24: 23 | C24: PDV-952I | D24: =_xlfn.XLOOKUP(C24,[1]생활용펌프가격표!$A:$A,[1]생활용펌프가격표!$B:$B,0) -> 396000 | E24: =_xlfn.XLOOKUP(C24,[1]생활용펌프가격표!$A:$A,[1]생활용펌프가격표!$C:$C,0) -> 349000 | H24: =1-E24/1.1/D24 -> 0.19880624 | I24: 윌로펌프모터 | J24: 이조 | K24: WILO 대리점
A25: PDV-950MA/h | B25: 24 | C25: PDV-950MA | D25: =_xlfn.XLOOKUP(A25,[1]생활용펌프가격표!$A:$A,[1]생활용펌프가격표!$B:$B,0) -> 438000 | E25: =_xlfn.XLOOKUP(A25,[1]생활용펌프가격표!$A:$A,[1]생활용펌프가격표!$C:$C,0) -> 386000 | H25: =1-E25/1.1/D25 -> 0.19883769 | I25: 이피컴퍼니 | J25: 이피컴퍼니 | K25: WILO 대리점
A26: PDV-950M/h | B26: 25 | C26: PDV-950M | D26: =_xlfn.XLOOKUP(A26,[1]생활용펌프가격표!$A:$A,[1]생활용펌프가격표!$B:$B,0) -> 413000 | E26: =_xlfn.XLOOKUP(A26,[1]생활용펌프가격표!$A:$A,[1]생활용펌프가격표!$C:$C,0) -> 364000 | H26: =1-E26/1.1/D26 -> 0.19876733 | I26: EP COMPANY | J26: 이피컴퍼니 | K26: WILO 대리점
A27: PDV-400MA/h | B27: 26 | C27: PDV-400MA | D27: =_xlfn.XLOOKUP(A27,[1]생활용펌프가격표!$A:$A,[1]생활용펌프가격표!$B:$B,0) -> 361000 | E27: =_xlfn.XLOOKUP(A27,[1]생활용펌프가격표!$A:$A,[1]생활용펌프가격표!$C:$C,0) -> 318000 | H27: =1-E27/1.1/D27 -> 0.19919416 | I27: 윌로펌프온라인쇼핑몰 | J27: 전진 | K27: WILO 대리점
A28: PDV-400M/h | B28: 27 | C28: PDV-400M | D28: =_xlfn.XLOOKUP(A28,[1]생활용펌프가격표!$A:$A,[1]생활용펌프가격표!$B:$B,0) -> 339000 | E28: =_xlfn.XLOOKUP(A28,[1]생활용펌프가격표!$A:$A,[1]생활용펌프가격표!$C:$C,0) -> 299000 | H28: =1-E28/1.1/D28 -> 0.19817645 | I28: 주식회사 리텍솔루션 | J28: 주식회사 리텍솔루션 | K28: WILO 대리점
B29: 28 | C29: PDV-300MA | D29: =_xlfn.XLOOKUP(C29,[1]생활용펌프가격표!$A:$A,[1]생활용펌프가격표!$B:$B,0) -> 230000 | E29: =_xlfn.XLOOKUP(C29,[1]생활용펌프가격표!$A:$A,[1]생활용펌프가격표!$C:$C,0) -> 203000 | H29: =1-E29/1.1/D29 -> 0.19762846 | I29: 주식회사 세종종합상사 | J29: 주식회사 세종종합상사 | K29: WILO 대리점
B30: 29 | C30: PDV-300M | D30: =_xlfn.XLOOKUP(C30,[1]생활용펌프가격표!$A:$A,[1]생활용펌프가격표!$B:$B,0) -> 218000 | E30: =_xlfn.XLOOKUP(C30,[1]생활용펌프가격표!$A:$A,[1]생활용펌프가격표!$C:$C,0) -> 192000 | H30: =1-E30/1.1/D30 -> 0.19933278 | I30: 여담고 | J30: 카토건설중기 | K30: WILO 대리점
B31: 30 | C31: PDN-1405I | D31: =_xlfn.XLOOKUP(C31,[1]생활용펌프가격표!$A:$A,[1]생활용펌프가격표!$B:$B,0) -> 469000 | E31: =_xlfn.XLOOKUP(C31,[1]생활용펌프가격표!$A:$A,[1]생활용펌프가격표!$C:$C,0) -> 413000 | H31: =1-E31/1.1/D31 -> 0.19945726 | I31: 주식회사 투빈 | J31: 투빈 | K31: WILO 대리점
B32: 31 | C32: PD-L901MA | D32: =_xlfn.XLOOKUP(C32,[1]생활용펌프가격표!$A:$A,[1]생활용펌프가격표!$B:$B,0) -> 367000 | E32: =_xlfn.XLOOKUP(C32,[1]생활용펌프가격표!$A:$A,[1]생활용펌프가격표!$C:$C,0) -> 323000 | H32: =1-E32/1.1/D32 -> 0.19990092 | I32: 펌프의 모든 것 | J32: 투빈 | K32: WILO 대리점
B33: 32 | C33: PD-L901M | D33: =_xlfn.XLOOKUP(C33,[1]생활용펌프가격표!$A:$A,[1]생활용펌프가격표!$B:$B,0) -> 345000 | E33: =_xlfn.XLOOKUP(C33,[1]생활용펌프가격표!$A:$A,[1]생활용펌프가격표!$C:$C,0) -> 304000 | H33: =1-E33/1.1/D33 -> 0.19894598 | I33: 펌프뱅크 | J33: 퍼맥스 | K33: WILO 대리점
B34: 33 | C34: PD-H953MA | D34: =_xlfn.XLOOKUP(C34,[1]생활용펌프가격표!$A:$A,[1]생활용펌프가격표!$B:$B,0) -> 451000 | E34: =_xlfn.XLOOKUP(C34,[1]생활용펌프가격표!$A:$A,[1]생활용펌프가격표!$C:$C,0) -> 397000 | H34: =1-E34/1.1/D34 -> 0.19975811 | I34: 펌스pums | J34: 펌스 | K34: WILO 대리점
B35: 34 | C35: PD-H953M | D35: =_xlfn.XLOOKUP(C35,[1]생활용펌프가격표!$A:$A,[1]생활용펌프가격표!$B:$B,0) -> 426000 | E35: =_xlfn.XLOOKUP(C35,[1]생활용펌프가격표!$A:$A,[1]생활용펌프가격표!$C:$C,0) -> 375000 | H35: =1-E35/1.1/D35 -> 0.19974392 | I35: 국제티에스펌프 | J35: 국제티에스 | K35: WILO 대리점
B36: 35 | C36: PD-A951MA | D36: =_xlfn.XLOOKUP(C36,[1]생활용펌프가격표!$A:$A,[1]생활용펌프가격표!$B:$B,0) -> 425000 | E36: =_xlfn.XLOOKUP(C36,[1]생활용펌프가격표!$A:$A,[1]생활용펌프가격표!$C:$C,0) -> 375000 | H36: =1-E36/1.1/D36 -> 0.19786096 | I36: 윈디샵 | J36: 하경상사 | K36: WILO 대리점
B37: 36 | C37: PD-A951M | D37: =_xlfn.XLOOKUP(C37,[1]생활용펌프가격표!$A:$A,[1]생활용펌프가격표!$B:$B,0) -> 401000 | E37: =_xlfn.XLOOKUP(C37,[1]생활용펌프가격표!$A:$A,[1]생활용펌프가격표!$C:$C,0) -> 353000 | H37: =1-E37/1.1/D37 -> 0.19972795 | I37: 신세계몰 | J37: 하경상사 | K37: WILO 대리점
B38: 37 | C38: PD-A601MA | D38: =_xlfn.XLOOKUP(C38,[1]생활용펌프가격표!$A:$A,[1]생활용펌프가격표!$B:$B,0) -> 343000 | E38: =_xlfn.XLOOKUP(C38,[1]생활용펌프가격표!$A:$A,[1]생활용펌프가격표!$C:$C,0) -> 302000 | H38: =1-E38/1.1/D38 -> 0.19957593 | I38: 펌프몰 | J38: 한일피엠
B39: 37 | C39: PD-A601M | D39: =_xlfn.XLOOKUP(C39,[1]생활용펌프가격표!$A:$A,[1]생활용펌프가격표!$B:$B,0) -> 315000 | E39: =_xlfn.XLOOKUP(C39,[1]생활용펌프가격표!$A:$A,[1]생활용펌프가격표!$C:$C,0) -> 278000 | H39: =1-E39/1.1/D39 -> 0.1976912 | I39: 광명상사 | J39: 광명상사 | K39: WILO 대리점
A40: PD-951MA/h | B40: 38 | C40: PD-951MA | D40: =_xlfn.XLOOKUP(A40,[1]생활용펌프가격표!$A:$A,[1]생활용펌프가격표!$B:$B,0) -> 438000 | E40: =_xlfn.XLOOKUP(A40,[1]생활용펌프가격표!$A:$A,[1]생활용펌프가격표!$C:$C,0) -> 386000 | H40: =1-E40/1.1/D40 -> 0.19883769 | I40: 신한일전기공식인증몰 | J40: 광명상사 | K40: WILO 대리점
...
